[2023-01-04 22:32:29,938] {taskinstance.py:1159} INFO - Dependencies all met for <TaskInstance: stock_data_pipeline_dag.create_cluster_dataproc_task manual__2023-01-04T22:32:28.280719+00:00 [queued]>
[2023-01-04 22:32:29,946] {taskinstance.py:1159} INFO - Dependencies all met for <TaskInstance: stock_data_pipeline_dag.create_cluster_dataproc_task manual__2023-01-04T22:32:28.280719+00:00 [queued]>
[2023-01-04 22:32:29,946] {taskinstance.py:1356} INFO - 
--------------------------------------------------------------------------------
[2023-01-04 22:32:29,947] {taskinstance.py:1357} INFO - Starting attempt 1 of 1
[2023-01-04 22:32:29,947] {taskinstance.py:1358} INFO - 
--------------------------------------------------------------------------------
[2023-01-04 22:32:29,958] {taskinstance.py:1377} INFO - Executing <Task(DataprocCreateClusterOperator): create_cluster_dataproc_task> on 2023-01-04 22:32:28.280719+00:00
[2023-01-04 22:32:29,968] {standard_task_runner.py:52} INFO - Started process 4188 to run task
[2023-01-04 22:32:29,972] {standard_task_runner.py:79} INFO - Running: ['***', 'tasks', 'run', 'stock_data_pipeline_dag', 'create_cluster_dataproc_task', 'manual__2023-01-04T22:32:28.280719+00:00', '--job-id', '22', '--raw', '--subdir', 'DAGS_FOLDER/stock_data_pipeline_dag.py', '--cfg-path', '/tmp/tmphwx2fpyy', '--error-file', '/tmp/tmpq_khf3uw']
[2023-01-04 22:32:29,974] {standard_task_runner.py:80} INFO - Job 22: Subtask create_cluster_dataproc_task
[2023-01-04 22:32:30,054] {task_command.py:370} INFO - Running <TaskInstance: stock_data_pipeline_dag.create_cluster_dataproc_task manual__2023-01-04T22:32:28.280719+00:00 [running]> on host e35cd2348433
[2023-01-04 22:32:30,139] {taskinstance.py:1569} INFO - Exporting the following env vars:
AIRFLOW_CTX_DAG_OWNER=***
AIRFLOW_CTX_DAG_ID=stock_data_pipeline_dag
AIRFLOW_CTX_TASK_ID=create_cluster_dataproc_task
AIRFLOW_CTX_EXECUTION_DATE=2023-01-04T22:32:28.280719+00:00
AIRFLOW_CTX_TRY_NUMBER=1
AIRFLOW_CTX_DAG_RUN_ID=manual__2023-01-04T22:32:28.280719+00:00
[2023-01-04 22:32:30,140] {dataproc.py:590} INFO - Creating cluster: move-data
[2023-01-04 22:32:30,141] {base.py:68} INFO - Using connection ID 'google_cloud_default' for task execution.
[2023-01-04 22:32:31,966] {taskinstance.py:1889} ERROR - Task failed with exception
Traceback (most recent call last):
  File "/home/airflow/.local/lib/python3.9/site-packages/google/api_core/grpc_helpers.py", line 50, in error_remapped_callable
    return callable_(*args, **kwargs)
  File "/home/airflow/.local/lib/python3.9/site-packages/grpc/_channel.py", line 946, in __call__
    return _end_unary_response_blocking(state, call, False, None)
  File "/home/airflow/.local/lib/python3.9/site-packages/grpc/_channel.py", line 849, in _end_unary_response_blocking
    raise _InactiveRpcError(state)
grpc._channel._InactiveRpcError: <_InactiveRpcError of RPC that terminated with:
	status = StatusCode.INVALID_ARGUMENT
	details = "User not authorized to act as service account '230775253-compute@developer.gserviceaccount.com'. To act as a service account, user must have one of [Owner, Editor, Service Account Actor] roles. See https://cloud.google.com/iam/docs/understanding-service-accounts for additional details."
	debug_error_string = "{"created":"@1672871551.965538384","description":"Error received from peer ipv4:142.251.166.95:443","file":"src/core/lib/surface/call.cc","file_line":966,"grpc_message":"User not authorized to act as service account '230775253-compute@developer.gserviceaccount.com'. To act as a service account, user must have one of [Owner, Editor, Service Account Actor] roles. See https://cloud.google.com/iam/docs/understanding-service-accounts for additional details.","grpc_status":3}"
>

The above exception was the direct cause of the following exception:

Traceback (most recent call last):
  File "/home/airflow/.local/lib/python3.9/site-packages/airflow/providers/google/cloud/operators/dataproc.py", line 598, in execute
    cluster = self._create_cluster(hook)
  File "/home/airflow/.local/lib/python3.9/site-packages/airflow/providers/google/cloud/operators/dataproc.py", line 521, in _create_cluster
    operation = hook.create_cluster(
  File "/home/airflow/.local/lib/python3.9/site-packages/airflow/providers/google/common/hooks/base_google.py", line 463, in inner_wrapper
    return func(self, *args, **kwargs)
  File "/home/airflow/.local/lib/python3.9/site-packages/airflow/providers/google/cloud/hooks/dataproc.py", line 305, in create_cluster
    result = client.create_cluster(
  File "/home/airflow/.local/lib/python3.9/site-packages/google/cloud/dataproc_v1/services/cluster_controller/client.py", line 560, in create_cluster
    response = rpc(
  File "/home/airflow/.local/lib/python3.9/site-packages/google/api_core/gapic_v1/method.py", line 154, in __call__
    return wrapped_func(*args, **kwargs)
  File "/home/airflow/.local/lib/python3.9/site-packages/google/api_core/retry.py", line 283, in retry_wrapped_func
    return retry_target(
  File "/home/airflow/.local/lib/python3.9/site-packages/google/api_core/retry.py", line 190, in retry_target
    return target()
  File "/home/airflow/.local/lib/python3.9/site-packages/google/api_core/timeout.py", line 99, in func_with_timeout
    return func(*args, **kwargs)
  File "/home/airflow/.local/lib/python3.9/site-packages/google/api_core/grpc_helpers.py", line 52, in error_remapped_callable
    raise exceptions.from_grpc_error(exc) from exc
google.api_core.exceptions.InvalidArgument: 400 User not authorized to act as service account '230775253-compute@developer.gserviceaccount.com'. To act as a service account, user must have one of [Owner, Editor, Service Account Actor] roles. See https://cloud.google.com/iam/docs/understanding-service-accounts for additional details.
[2023-01-04 22:32:31,979] {taskinstance.py:1395} INFO - Marking task as FAILED. dag_id=stock_data_pipeline_dag, task_id=create_cluster_dataproc_task, execution_date=20230104T223228, start_date=20230104T223229, end_date=20230104T223231
[2023-01-04 22:32:31,991] {standard_task_runner.py:92} ERROR - Failed to execute job 22 for task create_cluster_dataproc_task (400 User not authorized to act as service account '230775253-compute@developer.gserviceaccount.com'. To act as a service account, user must have one of [Owner, Editor, Service Account Actor] roles. See https://cloud.google.com/iam/docs/understanding-service-accounts for additional details.; 4188)
[2023-01-04 22:32:32,034] {local_task_job.py:156} INFO - Task exited with return code 1
