[2023-01-07 23:27:34,934] {taskinstance.py:1159} INFO - Dependencies all met for <TaskInstance: btc_data_pipeline_dag.trigger_dbt_cloud_job_run manual__2023-01-07T23:11:48.162146+00:00 [queued]>
[2023-01-07 23:27:34,944] {taskinstance.py:1159} INFO - Dependencies all met for <TaskInstance: btc_data_pipeline_dag.trigger_dbt_cloud_job_run manual__2023-01-07T23:11:48.162146+00:00 [queued]>
[2023-01-07 23:27:34,945] {taskinstance.py:1356} INFO - 
--------------------------------------------------------------------------------
[2023-01-07 23:27:34,945] {taskinstance.py:1357} INFO - Starting attempt 4 of 4
[2023-01-07 23:27:34,945] {taskinstance.py:1358} INFO - 
--------------------------------------------------------------------------------
[2023-01-07 23:27:34,958] {taskinstance.py:1377} INFO - Executing <Task(DbtCloudRunJobOperator): trigger_dbt_cloud_job_run> on 2023-01-07 23:11:48.162146+00:00
[2023-01-07 23:27:34,965] {standard_task_runner.py:52} INFO - Started process 4332 to run task
[2023-01-07 23:27:34,972] {standard_task_runner.py:79} INFO - Running: ['***', 'tasks', 'run', 'btc_data_pipeline_dag', 'trigger_dbt_cloud_job_run', 'manual__2023-01-07T23:11:48.162146+00:00', '--job-id', '121', '--raw', '--subdir', 'DAGS_FOLDER/btc_data_pipeline_dag.py', '--cfg-path', '/tmp/tmptcm1pqb6', '--error-file', '/tmp/tmpmusbvj6b']
[2023-01-07 23:27:34,973] {standard_task_runner.py:80} INFO - Job 121: Subtask trigger_dbt_cloud_job_run
[2023-01-07 23:27:35,042] {task_command.py:370} INFO - Running <TaskInstance: btc_data_pipeline_dag.trigger_dbt_cloud_job_run manual__2023-01-07T23:11:48.162146+00:00 [running]> on host 48dd7f56541e
[2023-01-07 23:27:35,114] {taskinstance.py:1569} INFO - Exporting the following env vars:
AIRFLOW_CTX_DAG_OWNER=***
AIRFLOW_CTX_DAG_ID=btc_data_pipeline_dag
AIRFLOW_CTX_TASK_ID=trigger_dbt_cloud_job_run
AIRFLOW_CTX_EXECUTION_DATE=2023-01-07T23:11:48.162146+00:00
AIRFLOW_CTX_TRY_NUMBER=4
AIRFLOW_CTX_DAG_RUN_ID=manual__2023-01-07T23:11:48.162146+00:00
[2023-01-07 23:27:35,124] {base.py:68} INFO - Using connection ID 'dbt_cloud' for task execution.
[2023-01-07 23:27:35,205] {http.py:148} INFO - Sending 'POST' to url: https://cloud.getdbt.com/api/v2/accounts/136764/jobs/192465/run/
[2023-01-07 23:27:35,340] {http.py:161} ERROR - HTTP error: Unauthorized
[2023-01-07 23:27:35,341] {http.py:162} ERROR - {"status": {"code": 401, "is_success": false, "user_message": "The API is not accessible to unpaid accounts.", "developer_message": null}, "data": null}
[2023-01-07 23:27:35,354] {taskinstance.py:1889} ERROR - Task failed with exception
Traceback (most recent call last):
  File "/home/airflow/.local/lib/python3.9/site-packages/airflow/providers/http/hooks/http.py", line 159, in check_response
    response.raise_for_status()
  File "/home/airflow/.local/lib/python3.9/site-packages/requests/models.py", line 1022, in raise_for_status
    raise HTTPError(http_error_msg, response=self)
requests.exceptions.HTTPError: 401 Client Error: Unauthorized for url: https://cloud.getdbt.com/api/v2/accounts/136764/jobs/192465/run/

During handling of the above exception, another exception occurred:

Traceback (most recent call last):
  File "/home/airflow/.local/lib/python3.9/site-packages/airflow/providers/dbt/cloud/operators/dbt.py", line 116, in execute
    trigger_job_response = self.hook.trigger_job_run(
  File "/home/airflow/.local/lib/python3.9/site-packages/airflow/providers/dbt/cloud/hooks/dbt.py", line 58, in wrapper
    return func(*bound_args.args, **bound_args.kwargs)
  File "/home/airflow/.local/lib/python3.9/site-packages/airflow/providers/dbt/cloud/hooks/dbt.py", line 315, in trigger_job_run
    return self._run_and_get_response(
  File "/home/airflow/.local/lib/python3.9/site-packages/airflow/providers/dbt/cloud/hooks/dbt.py", line 206, in _run_and_get_response
    return self.run(endpoint=endpoint, data=payload)
  File "/home/airflow/.local/lib/python3.9/site-packages/airflow/providers/http/hooks/http.py", line 149, in run
    return self.run_and_check(session, prepped_request, extra_options)
  File "/home/airflow/.local/lib/python3.9/site-packages/airflow/providers/http/hooks/http.py", line 202, in run_and_check
    self.check_response(response)
  File "/home/airflow/.local/lib/python3.9/site-packages/airflow/providers/http/hooks/http.py", line 163, in check_response
    raise AirflowException(str(response.status_code) + ":" + response.reason)
airflow.exceptions.AirflowException: 401:Unauthorized
[2023-01-07 23:27:35,358] {taskinstance.py:1395} INFO - Marking task as FAILED. dag_id=btc_data_pipeline_dag, task_id=trigger_dbt_cloud_job_run, execution_date=20230107T231148, start_date=20230107T232734, end_date=20230107T232735
[2023-01-07 23:27:35,369] {standard_task_runner.py:92} ERROR - Failed to execute job 121 for task trigger_dbt_cloud_job_run (401:Unauthorized; 4332)
[2023-01-07 23:27:35,387] {local_task_job.py:156} INFO - Task exited with return code 1
[2023-01-07 23:27:35,421] {local_task_job.py:273} INFO - 0 downstream tasks scheduled from follow-on schedule check
