[2023-01-04 21:51:50,647] {taskinstance.py:1159} INFO - Dependencies all met for <TaskInstance: stock_data_pipeline_dag.create_cluster_dataproc_task manual__2023-01-04T21:51:49.241677+00:00 [queued]>
[2023-01-04 21:51:50,656] {taskinstance.py:1159} INFO - Dependencies all met for <TaskInstance: stock_data_pipeline_dag.create_cluster_dataproc_task manual__2023-01-04T21:51:49.241677+00:00 [queued]>
[2023-01-04 21:51:50,656] {taskinstance.py:1356} INFO - 
--------------------------------------------------------------------------------
[2023-01-04 21:51:50,656] {taskinstance.py:1357} INFO - Starting attempt 1 of 1
[2023-01-04 21:51:50,656] {taskinstance.py:1358} INFO - 
--------------------------------------------------------------------------------
[2023-01-04 21:51:50,668] {taskinstance.py:1377} INFO - Executing <Task(DataprocCreateClusterOperator): create_cluster_dataproc_task> on 2023-01-04 21:51:49.241677+00:00
[2023-01-04 21:51:50,676] {standard_task_runner.py:52} INFO - Started process 2680 to run task
[2023-01-04 21:51:50,682] {standard_task_runner.py:79} INFO - Running: ['***', 'tasks', 'run', 'stock_data_pipeline_dag', 'create_cluster_dataproc_task', 'manual__2023-01-04T21:51:49.241677+00:00', '--job-id', '18', '--raw', '--subdir', 'DAGS_FOLDER/stock_data_pipeline_dag.py', '--cfg-path', '/tmp/tmphhxlx16z', '--error-file', '/tmp/tmpy6_1axuz']
[2023-01-04 21:51:50,683] {standard_task_runner.py:80} INFO - Job 18: Subtask create_cluster_dataproc_task
[2023-01-04 21:51:50,773] {task_command.py:370} INFO - Running <TaskInstance: stock_data_pipeline_dag.create_cluster_dataproc_task manual__2023-01-04T21:51:49.241677+00:00 [running]> on host e35cd2348433
[2023-01-04 21:51:50,874] {taskinstance.py:1569} INFO - Exporting the following env vars:
AIRFLOW_CTX_DAG_OWNER=***
AIRFLOW_CTX_DAG_ID=stock_data_pipeline_dag
AIRFLOW_CTX_TASK_ID=create_cluster_dataproc_task
AIRFLOW_CTX_EXECUTION_DATE=2023-01-04T21:51:49.241677+00:00
AIRFLOW_CTX_TRY_NUMBER=1
AIRFLOW_CTX_DAG_RUN_ID=manual__2023-01-04T21:51:49.241677+00:00
[2023-01-04 21:51:50,875] {dataproc.py:590} INFO - Creating cluster: move-data
[2023-01-04 21:51:50,878] {base.py:68} INFO - Using connection ID 'google_cloud_default' for task execution.
[2023-01-04 21:51:50,949] {taskinstance.py:1889} ERROR - Task failed with exception
Traceback (most recent call last):
  File "/home/airflow/.local/lib/python3.9/site-packages/google/api_core/grpc_helpers.py", line 50, in error_remapped_callable
    return callable_(*args, **kwargs)
  File "/home/airflow/.local/lib/python3.9/site-packages/grpc/_channel.py", line 946, in __call__
    return _end_unary_response_blocking(state, call, False, None)
  File "/home/airflow/.local/lib/python3.9/site-packages/grpc/_channel.py", line 849, in _end_unary_response_blocking
    raise _InactiveRpcError(state)
grpc._channel._InactiveRpcError: <_InactiveRpcError of RPC that terminated with:
	status = StatusCode.UNKNOWN
	details = "Stream removed"
	debug_error_string = "{"created":"@1672869110.948523144","description":"Error received from peer ipv4:142.250.123.95:443","file":"src/core/lib/surface/call.cc","file_line":966,"grpc_message":"Stream removed","grpc_status":2}"
>

The above exception was the direct cause of the following exception:

Traceback (most recent call last):
  File "/home/airflow/.local/lib/python3.9/site-packages/airflow/providers/google/cloud/operators/dataproc.py", line 598, in execute
    cluster = self._create_cluster(hook)
  File "/home/airflow/.local/lib/python3.9/site-packages/airflow/providers/google/cloud/operators/dataproc.py", line 521, in _create_cluster
    operation = hook.create_cluster(
  File "/home/airflow/.local/lib/python3.9/site-packages/airflow/providers/google/common/hooks/base_google.py", line 463, in inner_wrapper
    return func(self, *args, **kwargs)
  File "/home/airflow/.local/lib/python3.9/site-packages/airflow/providers/google/cloud/hooks/dataproc.py", line 305, in create_cluster
    result = client.create_cluster(
  File "/home/airflow/.local/lib/python3.9/site-packages/google/cloud/dataproc_v1/services/cluster_controller/client.py", line 560, in create_cluster
    response = rpc(
  File "/home/airflow/.local/lib/python3.9/site-packages/google/api_core/gapic_v1/method.py", line 154, in __call__
    return wrapped_func(*args, **kwargs)
  File "/home/airflow/.local/lib/python3.9/site-packages/google/api_core/retry.py", line 283, in retry_wrapped_func
    return retry_target(
  File "/home/airflow/.local/lib/python3.9/site-packages/google/api_core/retry.py", line 190, in retry_target
    return target()
  File "/home/airflow/.local/lib/python3.9/site-packages/google/api_core/timeout.py", line 99, in func_with_timeout
    return func(*args, **kwargs)
  File "/home/airflow/.local/lib/python3.9/site-packages/google/api_core/grpc_helpers.py", line 52, in error_remapped_callable
    raise exceptions.from_grpc_error(exc) from exc
google.api_core.exceptions.Unknown: None Stream removed
[2023-01-04 21:51:50,965] {taskinstance.py:1395} INFO - Marking task as FAILED. dag_id=stock_data_pipeline_dag, task_id=create_cluster_dataproc_task, execution_date=20230104T215149, start_date=20230104T215150, end_date=20230104T215150
[2023-01-04 21:51:50,982] {standard_task_runner.py:92} ERROR - Failed to execute job 18 for task create_cluster_dataproc_task (None Stream removed; 2680)
[2023-01-04 21:51:51,019] {local_task_job.py:156} INFO - Task exited with return code 1
